<?xml version="1.0"?>
<robot name="cylinder">
  <link name="base_link">
    <visual>
      <geometry>
        <cylinder length="1" radius="0.01"/>
      </geometry>
    </visual>
    <collision>
      <geometry>
        <cylinder length="1" radius="0.01"/>
      </geometry>
    </collision>
    <inertial>
        <origin rpy="0 0 0" xyz="0 0 0" />
        <mass value="1" />
        <inertia ixx="1" ixy="0" ixz="0" iyy="1" iyz="0" izz="1" />
  </inertial>
  </link>

  <link name="link1">
    <visual>
      <geometry>
        <sphere radius="0.1"/>
      </geometry>
    <material name="transparent"/>
    </visual>
    <collision>
      <geometry>
        <sphere radius="0.01"/>
      </geometry>
    </collision>
    <inertial>
        <origin rpy="0 0 0" xyz="0 0 0" />
        <mass value="1" />
        <inertia ixx="1" ixy="0" ixz="0" iyy="1" iyz="0" izz="1" />
    </inertial>
  </link>

  <joint name="translationY" type="prismatic">
    <parent link="base_link"/>
    <child link="link1"/>
    <origin rpy="0 0 0" xyz="0 0 0"/>
	<axis xyz="0 0 -1"/>
    <limit effort="10000" lower="-1000" upper="1000.0" velocity="1"/>
  </joint>


</robot>