<?xml version="1.0" ?>


<!-- =================================================================================== -->
<!-- |    This document was autogenerated by xacro from allegro_hand_description/urdf/allegro_hand_description.xacro | -->
<!-- |    EDITING THIS FILE BY HAND IS NOT RECOMMENDED                                 | -->
<!-- =================================================================================== -->
<robot name="allegro_hand">


    <link name="base_link">
  </link>


  <joint name="translationX" type="prismatic">
    <parent link="base_link"/>
    <child link="base_link2"/>
    <origin rpy="0 0 0" xyz="0 0 0"/>
	<axis xyz="1 0 0"/>
    <limit effort="20" lower="-1000" upper="1000.0" velocity="1"/>
    <dynamics damping="0.00001"/>
  </joint>

  <link name="base_link2">
  </link>

  <joint name="translationY" type="prismatic">
    <parent link="base_link2"/>
    <child link="base_link3"/>
    <origin rpy="0 0 0" xyz="0 0 0"/>
	<axis xyz="0 1 0"/>
    <limit effort="10000" lower="-1000" upper="1000.0" velocity="1"/>
  </joint>

 <link name="base_link3">
  </link>

  <joint name="translationZ" type="prismatic">
    <parent link="base_link3"/>
    <child link="base_link4"/>
    <origin rpy="0 0 0" xyz="0 0 0"/>
	<axis xyz="0 0 1"/>
    <limit effort="20" lower="-100" upper="100.0" velocity="0.2"/>
  </joint>

  <link name="base_link4">
  </link>

  <joint name="rotationX" type="revolute">
    <parent link="base_link4"/>
    <child link="base_link5"/>
    <origin rpy="0 0 0" xyz="0 0 0"/>
	<axis xyz="1 0 0"/>
    <limit effort="20" lower="-100.0" upper="100.0" velocity="0.2"/>

  </joint>

<link name="base_link5">
  </link>

  <joint name="rotationY" type="revolute">
    <parent link="base_link5"/>
    <child link="base_link6"/>
    <origin rpy="0 0 0" xyz="0 0 0"/>
	<axis xyz="0 1 0"/>
    <limit effort="20" lower="-100.0" upper="100.0" velocity="0.2"/>
  </joint>

<link name="base_link6">
  </link>

  <joint name="rotationZ" type="revolute">
    <parent link="base_link6"/>
    <child link="palm_link"/>
    <origin rpy="0 0 0" xyz="0 0 0"/>
	<axis xyz="0 0 1"/>
    <limit effort="20" lower="-100.0" upper="100.0" velocity="0.2"/>
  </joint>


  <!-- ============================================================================= -->
  <!-- PALM -->
  <link name="palm_link">
    <visual>
      <geometry>
        <mesh filename="allegro_hand/allegro_hand_description/meshes/base_link_right.STL"/>
      </geometry>
      <origin rpy="0 0 0" xyz="0 0 0 "/>
      <material name="black">
        <color rgba="0.2 0.2 0.2 1"/>
      </material>
    </visual>
    <collision>
      <origin rpy="0 0 0" xyz="-0.009300 0 -0.0475"/>
      <geometry>
        <box size="0.0408 0.1130 0.095"/>
      </geometry>
    </collision>
    <inertial>
      <origin rpy="0 0 0" xyz="0 0 0.0475"/>
      <mass value="0.4154"/>
      <inertia ixx="1e-4" ixy="0.0" ixz="0.0" iyy="1e-4" iyz="0.0" izz="1e-4"/>
    </inertial>
  </link>
  <!-- END THUMB MACRO -->
  <!-- [[END]] THREE FINGER MACRO -->
  <!-- [LINK 0, 4, 8] -->
  <link name="link_00">
    <visual>
      <geometry>
        <mesh filename="allegro_hand/allegro_hand_description/meshes/link_0.0.STL"/>
      </geometry>
      <material name="black"/>
    </visual>
    <collision>
      <geometry>
        <box size="0.0196 0.0275 0.0164"/>
      </geometry>
      <origin rpy="0 0 0" xyz="0 0 0.0082"/>
    </collision>
    <inertial>
      <mass value="0.0119"/>
      <origin rpy="0 0 0" xyz="0 0 0"/>
      <inertia ixx="1.01666658333e-06" ixy="0.0" ixz="0.0" iyy="6.47677333333e-07" iyz="0.0" izz="1.01666658333e-06"/>
    </inertial>
  </link>
  <joint name="joint_00" type="revolute">
    <axis xyz="0 0 1"/>
    <limit effort="0.71" lower="0.47" upper="-0.47" velocity="0.12"/>
    <parent link="palm_link"/>
    <child link="link_00"/>
    <origin rpy="-0.08726646254999999 0 0" xyz="0 0.0435 -0.001542"/>
    <dynamics damping="0.1" friction="0.01"/>
  </joint>
  <!-- [LINK 1, 5, 9] -->
  <link name="link_01">
    <visual>
      <geometry>
        <mesh filename="allegro_hand/allegro_hand_description/meshes/link_1.0.STL"/>
      </geometry>
      <material name="black"/>
    </visual>
    <collision>
      <geometry>
        <box size="0.0196 0.0275 0.054"/>
      </geometry>
      <origin rpy="0 0 0" xyz="0 0 0.027"/>
    </collision>
    <inertial>
      <mass value="0.065"/>
      <origin rpy="0 0 0" xyz="0 0 0"/>
      <inertia ixx="7.95654166667e-05" ixy="1.7199e-05" ixz="8.75875e-06" iyy="2.47088833333e-05" iyz="2.413125e-05" izz="7.95654166667e-05"/>
    </inertial>
  </link>
  <joint name="joint_01" type="revolute">
    <limit effort="50" lower="1.6099999999999999" upper="-0.19599999999999998" velocity="4"/>
    <axis xyz="0 1 0"/>
    <parent link="link_00"/>
    <child link="link_01"/>
    <origin xyz="0 0 0.0164"/>
    <dynamics damping="0.1" friction="0.01"/>
  </joint>
  <!-- [LINK 2, 6, 10]-->
  <link name="link_02">
    <visual>
      <geometry>
        <mesh filename="allegro_hand/allegro_hand_description/meshes/link_2.0.STL"/>
      </geometry>
      <material name="black"/>
    </visual>
    <collision>
      <geometry>
        <box size="0.0196 0.0275 0.0384"/>
      </geometry>
      <origin rpy="0 0 0" xyz="0 0 0.0192"/>
    </collision>
    <inertial>
      <mass value="0.0355"/>
      <origin rpy="0 0 0" xyz="0 0 0"/>
      <inertia ixx="2.63979183333e-05" ixy="6.67968e-06" ixz="4.783625e-06" iyy="1.34948516667e-05" iyz="9.372e-06" izz="2.63979183333e-05"/>
    </inertial>
  </link>
  <joint name="joint_02" type="revolute">
    <axis xyz="0 1 0"/>
    <limit effort="50" lower="1.7089999999999999" upper="-0.17400000000000002" velocity="4"/>
    <parent link="link_01"/>
    <child link="link_02"/>
    <origin xyz="0 0 0.054"/>
    <dynamics damping="0.1" friction="0.01"/>
  </joint>
  <!-- [LINK 3, 7, 11] -->
  <link name="link_03">
    <visual>
      <geometry>
        <mesh filename="allegro_hand/allegro_hand_description/meshes/link_3.0.STL"/>
      </geometry>
      <material name="black"/>
    </visual>
    <collision>
      <geometry>
        <box size="0.0196 0.0275 0.026699999999999998"/>
      </geometry>
      <origin rpy="0 0 0" xyz="0 0 0.013349999999999999"/>
    </collision>
    <inertial>
      <mass value="0.0096"/>
      <origin rpy="0 0 0" xyz="0 0 0"/>
      <inertia ixx="4.701248e-06" ixy="1.255968e-06" ixz="1.2936e-06" iyy="3.649312e-06" iyz="1.7622e-06" izz="4.701248e-06"/>
    </inertial>
  </link>
  <joint name="joint_03" type="revolute">
    <axis xyz="0 1 0"/>
    <limit effort="50" lower="1.6179999999999999" upper="-0.227" velocity="4"/>
    <parent link="link_02"/>
    <child link="link_03"/>
    <origin xyz="0 0 0.0384"/>
    <dynamics damping="0.1" friction="0.01"/>
  </joint>
  <!-- [FINGER TIP] -->
  <link name="link_03_tip">
    <visual>
      <geometry>
        <mesh filename="allegro_hand/allegro_hand_description/meshes/link_3.0_tip.STL"/>
      </geometry>
      <material name="white">
        <color rgba=".9 .9 .9 1"/>
      </material>
    </visual>
    <collision>
      <geometry>
        <sphere radius="0.012"/>
      </geometry>
    </collision>
    <inertial>
      <mass value="0.0168"/>
      <origin rpy="0 0 0" xyz="0 0 0"/>
      <inertia ixx="9.68e-07" ixy="0" ixz="0" iyy="9.68e-07" iyz="0" izz="9.68e-07"/>
    </inertial>
  </link>
  <joint name="joint_03_tip" type="fixed">
    <parent link="link_03"/>
    <child link="link_03_tip"/>
    <origin rpy="0 0 0" xyz="0 0 0.026699999999999998"/>
  </joint>
  <!-- [LINK 0, 4, 8] -->
  <link name="link_04">
    <visual>
      <geometry>
        <mesh filename="allegro_hand/allegro_hand_description/meshes/link_0.0.STL"/>
      </geometry>
      <material name="black"/>
    </visual>
    <collision>
      <geometry>
        <box size="0.0196 0.0275 0.0164"/>
      </geometry>
      <origin rpy="0 0 0" xyz="0 0 0.0082"/>
    </collision>
    <inertial>
      <mass value="0.0119"/>
      <origin rpy="0 0 0" xyz="0 0 0"/>
      <inertia ixx="1.01666658333e-06" ixy="0.0" ixz="0.0" iyy="6.47677333333e-07" iyz="0.0" izz="1.01666658333e-06"/>
    </inertial>
  </link>
  <joint name="joint_04" type="revolute">
    <axis xyz="0 0 1"/>
    <limit effort="0.71" lower="0.47" upper="-0.47" velocity="0.12"/>
    <parent link="palm_link"/>
    <child link="link_04"/>
    <origin rpy="0.0 0 0" xyz="0 0 0.0007"/>
    <dynamics damping="0.1" friction="0.01"/>
  </joint>
  <!-- [LINK 1, 5, 9] -->
  <link name="link_05">
    <visual>
      <geometry>
        <mesh filename="allegro_hand/allegro_hand_description/meshes/link_1.0.STL"/>
      </geometry>
      <material name="black"/>
    </visual>
    <collision>
      <geometry>
        <box size="0.0196 0.0275 0.054"/>
      </geometry>
      <origin rpy="0 0 0" xyz="0 0 0.027"/>
    </collision>
    <inertial>
      <mass value="0.065"/>
      <origin rpy="0 0 0" xyz="0 0 0"/>
      <inertia ixx="7.95654166667e-05" ixy="1.7199e-05" ixz="8.75875e-06" iyy="2.47088833333e-05" iyz="2.413125e-05" izz="7.95654166667e-05"/>
    </inertial>
  </link>
  <joint name="joint_05" type="revolute">
    <limit effort="50" lower="1.6099999999999999" upper="-0.19599999999999998" velocity="4"/>
    <axis xyz="0 1 0"/>
    <parent link="link_04"/>
    <child link="link_05"/>
    <origin xyz="0 0 0.0164"/>
    <dynamics damping="0.1" friction="0.01"/>
  </joint>
  <!-- [LINK 2, 6, 10]-->
  <link name="link_06">
    <visual>
      <geometry>
        <mesh filename="allegro_hand/allegro_hand_description/meshes/link_2.0.STL"/>
      </geometry>
      <material name="black"/>
    </visual>
    <collision>
      <geometry>
        <box size="0.0196 0.0275 0.0384"/>
      </geometry>
      <origin rpy="0 0 0" xyz="0 0 0.0192"/>
    </collision>
    <inertial>
      <mass value="0.0355"/>
      <origin rpy="0 0 0" xyz="0 0 0"/>
      <inertia ixx="2.63979183333e-05" ixy="6.67968e-06" ixz="4.783625e-06" iyy="1.34948516667e-05" iyz="9.372e-06" izz="2.63979183333e-05"/>
    </inertial>
  </link>
  <joint name="joint_06" type="revolute">
    <axis xyz="0 1 0"/>
    <limit effort="50" lower="1.7089999999999999" upper="-0.17400000000000002" velocity="4"/>
    <parent link="link_05"/>
    <child link="link_06"/>
    <origin xyz="0 0 0.054"/>
    <dynamics damping="0.1" friction="0.01"/>
  </joint>
  <!-- [LINK 3, 7, 11] -->
  <link name="link_07">
    <visual>
      <geometry>
        <mesh filename="allegro_hand/allegro_hand_description/meshes/link_3.0.STL"/>
      </geometry>
      <material name="black"/>
    </visual>
    <collision>
      <geometry>
        <box size="0.0196 0.0275 0.026699999999999998"/>
      </geometry>
      <origin rpy="0 0 0" xyz="0 0 0.013349999999999999"/>
    </collision>
    <inertial>
      <mass value="0.0096"/>
      <origin rpy="0 0 0" xyz="0 0 0"/>
      <inertia ixx="4.701248e-06" ixy="1.255968e-06" ixz="1.2936e-06" iyy="3.649312e-06" iyz="1.7622e-06" izz="4.701248e-06"/>
    </inertial>
  </link>
  <joint name="joint_07" type="revolute">
    <axis xyz="0 1 0"/>
    <limit effort="50" lower="1.6179999999999999" upper="-0.227" velocity="4"/>
    <parent link="link_06"/>
    <child link="link_07"/>
    <origin xyz="0 0 0.0384"/>
    <dynamics damping="0.1" friction="0.01"/>
  </joint>
  <!-- [FINGER TIP] -->
  <link name="link_07_tip">
    <visual>
      <geometry>
        <mesh filename="allegro_hand/allegro_hand_description/meshes/link_3.0_tip.STL"/>
      </geometry>
      <material name="white">
        <color rgba=".9 .9 .9 1"/>
      </material>
    </visual>
    <collision>
      <geometry>
        <sphere radius="0.012"/>
      </geometry>
    </collision>
    <inertial>
      <mass value="0.0168"/>
      <origin rpy="0 0 0" xyz="0 0 0"/>
      <inertia ixx="9.68e-07" ixy="0" ixz="0" iyy="9.68e-07" iyz="0" izz="9.68e-07"/>
    </inertial>
  </link>
  <joint name="joint_07_tip" type="fixed">
    <parent link="link_07"/>
    <child link="link_07_tip"/>
    <origin rpy="0 0 0" xyz="0 0 0.026699999999999998"/>
  </joint>
  <!-- [LINK 0, 4, 8] -->
  <link name="link_08">
    <visual>
      <geometry>
        <mesh filename="allegro_hand/allegro_hand_description/meshes/link_0.0.STL"/>
      </geometry>
      <material name="black"/>
    </visual>
    <collision>
      <geometry>
        <box size="0.0196 0.0275 0.0164"/>
      </geometry>
      <origin rpy="0 0 0" xyz="0 0 0.0082"/>
    </collision>
    <inertial>
      <mass value="0.0119"/>
      <origin rpy="0 0 0" xyz="0 0 0"/>
      <inertia ixx="1.01666658333e-06" ixy="0.0" ixz="0.0" iyy="6.47677333333e-07" iyz="0.0" izz="1.01666658333e-06"/>
    </inertial>
  </link>
  <joint name="joint_08" type="revolute">
    <axis xyz="0 0 1"/>
    <limit effort="50" lower="0.47" upper="-0.47" velocity="0.12"/>
    <parent link="palm_link"/>
    <child link="link_08"/>
    <origin rpy="0.08726646254999999 0 0" xyz="0 -0.0435 -0.001542"/>
    <dynamics damping="0.1" friction="0.01"/>
  </joint>
  <!-- [LINK 1, 5, 9] -->
  <link name="link_09">
    <visual>
      <geometry>
        <mesh filename="allegro_hand/allegro_hand_description/meshes/link_1.0.STL"/>
      </geometry>
      <material name="black"/>
    </visual>
    <collision>
      <geometry>
        <box size="0.0196 0.0275 0.054"/>
      </geometry>
      <origin rpy="0 0 0" xyz="0 0 0.027"/>
    </collision>
    <inertial>
      <mass value="0.065"/>
      <origin rpy="0 0 0" xyz="0 0 0"/>
      <inertia ixx="7.95654166667e-05" ixy="1.7199e-05" ixz="8.75875e-06" iyy="2.47088833333e-05" iyz="2.413125e-05" izz="7.95654166667e-05"/>
    </inertial>
  </link>
  <joint name="joint_09" type="revolute">
    <limit effort="50" lower="1.6099999999999999" upper="-0.19599999999999998" velocity="4"/>
    <axis xyz="0 1 0"/>
    <parent link="link_08"/>
    <child link="link_09"/>
    <origin xyz="0 0 0.0164"/>
    <dynamics damping="0.1" friction="0.01"/>
  </joint>
  <!-- [LINK 2, 6, 10]-->
  <link name="link_10">
    <visual>
      <geometry>
        <mesh filename="allegro_hand/allegro_hand_description/meshes/link_2.0.STL"/>
      </geometry>
      <material name="black"/>
    </visual>
    <collision>
      <geometry>
        <box size="0.0196 0.0275 0.0384"/>
      </geometry>
      <origin rpy="0 0 0" xyz="0 0 0.0192"/>
    </collision>
    <inertial>
      <mass value="0.0355"/>
      <origin rpy="0 0 0" xyz="0 0 0"/>
      <inertia ixx="2.63979183333e-05" ixy="6.67968e-06" ixz="4.783625e-06" iyy="1.34948516667e-05" iyz="9.372e-06" izz="2.63979183333e-05"/>
    </inertial>
  </link>
  <joint name="joint_10" type="revolute">
    <axis xyz="0 1 0"/>
    <limit effort="50" lower="1.7089999999999999" upper="-0.17400000000000002" velocity="4"/>
    <parent link="link_09"/>
    <child link="link_10"/>
    <origin xyz="0 0 0.054"/>
    <dynamics damping="0.1" friction="0.01"/>
  </joint>
  <!-- [LINK 3, 7, 11] -->
  <link name="link_11">
    <visual>
      <geometry>
        <mesh filename="allegro_hand/allegro_hand_description/meshes/link_3.0.STL"/>
      </geometry>
      <material name="black"/>
    </visual>
    <collision>
      <geometry>
        <box size="0.0196 0.0275 0.026699999999999998"/>
      </geometry>
      <origin rpy="0 0 0" xyz="0 0 0.013349999999999999"/>
    </collision>
    <inertial>
      <mass value="0.0096"/>
      <origin rpy="0 0 0" xyz="0 0 0"/>
      <inertia ixx="4.701248e-06" ixy="1.255968e-06" ixz="1.2936e-06" iyy="3.649312e-06" iyz="1.7622e-06" izz="4.701248e-06"/>
    </inertial>
  </link>
  <joint name="joint_11" type="revolute">
    <axis xyz="0 1 0"/>
    <limit effort="50" lower="1.6179999999999999" upper="-0.227" velocity="4"/>
    <parent link="link_10"/>
    <child link="link_11"/>
    <origin xyz="0 0 0.0384"/>
    <dynamics damping="0.1" friction="0.01"/>
  </joint>
  <!-- [FINGER TIP] -->
  <link name="link_11_tip">
    <visual>
      <geometry>
        <mesh filename="allegro_hand/allegro_hand_description/meshes/link_3.0_tip.STL"/>
      </geometry>
      <material name="white">
        <color rgba=".9 .9 .9 1"/>
      </material>
    </visual>
    <collision>
      <geometry>
        <sphere radius="0.012"/>
      </geometry>
    </collision>
    <inertial>
      <mass value="0.0168"/>
      <origin rpy="0 0 0" xyz="0 0 0"/>
      <inertia ixx="9.68e-07" ixy="0" ixz="0" iyy="9.68e-07" iyz="0" izz="9.68e-07"/>
    </inertial>
  </link>
  <joint name="joint_11_tip" type="fixed">
    <parent link="link_11"/>
    <child link="link_11_tip"/>
    <origin rpy="0 0 0" xyz="0 0 0.026699999999999998"/>
  </joint>
  <!-- [LINK 12] -->
  <link name="link_12">
    <visual>
      <geometry>
        <mesh filename="allegro_hand/allegro_hand_description/meshes/link_12.0_right.STL"/>
      </geometry>
      <material name="black">
        <color rgba=".2 .2 .2 1"/>
      </material>
      <origin rpy="0.0 0 0" xyz="0 0 0"/>
    </visual>
    <collision>
      <geometry>
        <box size="0.0358 0.034 0.0455"/>
      </geometry>
      <origin rpy="0 0 0" xyz="-0.0179 0.009 0.0145"/>
    </collision>
    <inertial>
      <mass value="0.0176"/>
      <origin rpy="0 0 0" xyz="0 0 0"/>
      <inertia ixx="1.89273333333e-5" ixy="7.16716e-06" ixz="5.35568e-06" iyy="1.43008213333e-05" iyz="6.8068e-06" izz="1.89273333333e-05"/>
    </inertial>
  </link>
  <joint name="joint_12" type="revolute">
    <axis xyz="-1 0 0"/>
    <limit effort="0.71" lower="0.46299999999999997" upper="1.396" velocity="0.12"/>
    <parent link="palm_link"/>
    <child link="link_12"/>
    <origin rpy="0 -1.6580627884499999 -1.5707963259" xyz="-0.0182 0.019333 -0.045987"/>
    <dynamics damping="0.1" friction="0.01"/>
  </joint>
  <!-- [LINK 13] -->
  <link name="link_13">
    <visual>
      <geometry>
        <mesh filename="allegro_hand/allegro_hand_description/meshes/link_13.0.STL"/>
      </geometry>
      <material name="black">
        <color rgba=".2 .2 .2 1"/>
      </material>
    </visual>
    <collision>
      <geometry>
        <box size="0.0196 0.0275 0.0177"/>
      </geometry>
      <origin rpy="0 0 0" xyz="0 0 0.00885"/>
    </collision>
    <inertial>
      <mass value="0.0119"/>
      <origin rpy="0 0 0" xyz="0 0 0"/>
      <inertia ixx="4.24250866667e-06" ixy="1.032087e-06" ixz="1.603525e-06" iyy="4.52362633333e-06" iyz="1.44808125e-06" izz="4.24250866667e-06"/>
    </inertial>
  </link>
  <joint name="joint_13" type="revolute">
    <axis xyz="0 0 1"/>
    <limit effort="50" lower="1.1629999999999998" upper="-0.10499999999999998" velocity="4"/>
    <parent link="link_12"/>
    <child link="link_13"/>
    <origin xyz="-0.027 0.005 0.0399"/>
    <dynamics damping="0.1" friction="0.01"/>
  </joint>
  <!-- [LINK 14] -->
  <link name="link_14">
    <visual>
      <geometry>
        <mesh filename="allegro_hand/allegro_hand_description/meshes/link_14.0.STL"/>
      </geometry>
      <material name="black">
                </material>
    </visual>
    <collision>
      <geometry>
        <box size="0.0196 0.0275 0.0514"/>
      </geometry>
      <origin rpy="0 0 0" xyz="0 0 0.0257"/>
    </collision>
    <inertial>
      <mass value="0.038"/>
      <origin rpy="0 0 0" xyz="0 0 0"/>
      <inertia ixx="4.30439933333e-05" ixy="9.57068e-06" ixz="5.1205e-06" iyy="1.44451933333e-05" iyz="1.342825e-05" izz="4.30439933333e-05"/>
    </inertial>
  </link>
  <joint name="joint_14" type="revolute">
    <axis xyz="0 1 0"/>
    <limit effort="50" lower="1.644" upper="-0.18899999999999997" velocity="4"/>
    <parent link="link_13"/>
    <child link="link_14"/>
    <origin xyz="0 0 0.0177"/>
    <dynamics damping="0.1" friction="0.01"/>
  </joint>
  <!-- [LINK 15] -->
  <link name="link_15">
    <visual>
      <geometry>
        <mesh filename="allegro_hand/allegro_hand_description/meshes/link_15.0.STL"/>
      </geometry>
      <material name="black">
                </material>
    </visual>
    <collision>
      <geometry>
        <box size="0.0196 0.0275 0.042300000000000004"/>
      </geometry>
      <origin rpy="0 0 0" xyz="0 0 0.021150000000000002"/>
    </collision>
    <inertial>
      <mass value="0.0388"/>
      <origin rpy="0 0 0" xyz="0 0 0"/>
      <inertia ixx="3.29223173333e-05" ixy="8.042076e-06" ixz="5.2283e-06" iyy="1.47493026667e-5" iyz="1.1283525e-5" izz="3.29223173333e-05"/>
    </inertial>
  </link>
  <joint name="joint_15" type="revolute">
    <axis xyz="0 1 0"/>
    <limit effort="50" lower="1.7189999999999999" upper="-0.162" velocity="4"/>
    <parent link="link_14"/>
    <child link="link_15"/>
    <origin xyz="0 0 0.0514"/>
    <dynamics damping="0.1" friction="0.01"/>
  </joint>
  <!-- [FINGER TIP] -->
  <link name="link_15_tip">
    <visual>
      <geometry>
        <mesh filename="allegro_hand/allegro_hand_description/meshes/link_15.0_tip.STL"/>
      </geometry>
      <material name="white">
        <color rgba=".9 .9 .9 1"/>
      </material>
    </visual>
    <collision>
      <geometry>
        <sphere radius="0.012"/>
      </geometry>
      <origin rpy="0 0 0" xyz="0 0 0"/>
    </collision>
    <inertial>
      <mass value="0.0168"/>
      <origin rpy="0 0 0" xyz="0 0 0"/>
      <inertia ixx="9.68e-07" ixy="0" ixz="0" iyy="9.68e-07" iyz="0" izz="9.68e-07"/>
    </inertial>
  </link>
  <joint name="joint_15_tip" type="fixed">
    <parent link="link_15"/>
    <child link="link_15_tip"/>
    <origin rpy="0 0 0" xyz="0 0 0.042300000000000004"/>
  </joint>
  <!-- ============================= GAZEBO SIMULATION ============================= -->

  <transmission name="joint_00_trans">
    <type>transmission_interface/SimpleTransmission</type>
    <joint name="joint_00">
      <hardwareInterface>hardware_interface/EffortJointInterface</hardwareInterface>
    </joint>
    <actuator name="joint_00_motor">
      <mechanicalReduction>1</mechanicalReduction>
      <hardwareInterface>hardware_interface/EffortJointInterface</hardwareInterface>
    </actuator>
  </transmission>
  <transmission name="joint_01_trans">
    <type>transmission_interface/SimpleTransmission</type>
    <joint name="joint_01">
      <hardwareInterface>hardware_interface/EffortJointInterface</hardwareInterface>
    </joint>
    <actuator name="joint_01_motor">
      <mechanicalReduction>1</mechanicalReduction>
      <hardwareInterface>hardware_interface/EffortJointInterface</hardwareInterface>
    </actuator>
  </transmission>
  <transmission name="joint_02_trans">
    <type>transmission_interface/SimpleTransmission</type>
    <joint name="joint_02">
      <hardwareInterface>hardware_interface/EffortJointInterface</hardwareInterface>
    </joint>
    <actuator name="joint_02_motor">
      <mechanicalReduction>1</mechanicalReduction>
      <hardwareInterface>hardware_interface/EffortJointInterface</hardwareInterface>
    </actuator>
  </transmission>
  <transmission name="joint_03_trans">
    <type>transmission_interface/SimpleTransmission</type>
    <joint name="joint_03">
      <hardwareInterface>hardware_interface/EffortJointInterface</hardwareInterface>
    </joint>
    <actuator name="joint_03_motor">
      <mechanicalReduction>1</mechanicalReduction>
      <hardwareInterface>hardware_interface/EffortJointInterface</hardwareInterface>
    </actuator>
  </transmission>
  <transmission name="joint_04_trans">
    <type>transmission_interface/SimpleTransmission</type>
    <joint name="joint_04">
      <hardwareInterface>hardware_interface/EffortJointInterface</hardwareInterface>
    </joint>
    <actuator name="joint_04_motor">
      <mechanicalReduction>1</mechanicalReduction>
      <hardwareInterface>hardware_interface/EffortJointInterface</hardwareInterface>
    </actuator>
  </transmission>
  <transmission name="joint_05_trans">
    <type>transmission_interface/SimpleTransmission</type>
    <joint name="joint_05">
      <hardwareInterface>hardware_interface/EffortJointInterface</hardwareInterface>
    </joint>
    <actuator name="joint_05_motor">
      <mechanicalReduction>1</mechanicalReduction>
      <hardwareInterface>hardware_interface/EffortJointInterface</hardwareInterface>
    </actuator>
  </transmission>
  <transmission name="joint_06_trans">
    <type>transmission_interface/SimpleTransmission</type>
    <joint name="joint_06">
      <hardwareInterface>hardware_interface/EffortJointInterface</hardwareInterface>
    </joint>
    <actuator name="joint_06_motor">
      <mechanicalReduction>1</mechanicalReduction>
      <hardwareInterface>hardware_interface/EffortJointInterface</hardwareInterface>
    </actuator>
  </transmission>
  <transmission name="joint_07_trans">
    <type>transmission_interface/SimpleTransmission</type>
    <joint name="joint_07">
      <hardwareInterface>hardware_interface/EffortJointInterface</hardwareInterface>
    </joint>
    <actuator name="joint_07_motor">
      <mechanicalReduction>1</mechanicalReduction>
      <hardwareInterface>hardware_interface/EffortJointInterface</hardwareInterface>
    </actuator>
  </transmission>
  <transmission name="joint_08_trans">
    <type>transmission_interface/SimpleTransmission</type>
    <joint name="joint_08">
      <hardwareInterface>hardware_interface/EffortJointInterface</hardwareInterface>
    </joint>
    <actuator name="joint_08_motor">
      <mechanicalReduction>1</mechanicalReduction>
      <hardwareInterface>hardware_interface/EffortJointInterface</hardwareInterface>
    </actuator>
  </transmission>
  <transmission name="joint_09_trans">
    <type>transmission_interface/SimpleTransmission</type>
    <joint name="joint_09">
      <hardwareInterface>hardware_interface/EffortJointInterface</hardwareInterface>
    </joint>
    <actuator name="joint_09_motor">
      <mechanicalReduction>1</mechanicalReduction>
      <hardwareInterface>hardware_interface/EffortJointInterface</hardwareInterface>
    </actuator>
  </transmission>
  <transmission name="joint_10_trans">
    <type>transmission_interface/SimpleTransmission</type>
    <joint name="joint_10">
      <hardwareInterface>hardware_interface/EffortJointInterface</hardwareInterface>
    </joint>
    <actuator name="joint_10_motor">
      <mechanicalReduction>1</mechanicalReduction>
      <hardwareInterface>hardware_interface/EffortJointInterface</hardwareInterface>
    </actuator>
  </transmission>
  <transmission name="joint_11_trans">
    <type>transmission_interface/SimpleTransmission</type>
    <joint name="joint_11">
      <hardwareInterface>hardware_interface/EffortJointInterface</hardwareInterface>
    </joint>
    <actuator name="joint_11_motor">
      <mechanicalReduction>1</mechanicalReduction>
      <hardwareInterface>hardware_interface/EffortJointInterface</hardwareInterface>
    </actuator>
  </transmission>
  <transmission name="joint_12_trans">
    <type>transmission_interface/SimpleTransmission</type>
    <joint name="joint_12">
      <hardwareInterface>hardware_interface/EffortJointInterface</hardwareInterface>
    </joint>
    <actuator name="joint_12_motor">
      <mechanicalReduction>1</mechanicalReduction>
      <hardwareInterface>hardware_interface/EffortJointInterface</hardwareInterface>
    </actuator>
  </transmission>
  <transmission name="joint_13_trans">
    <type>transmission_interface/SimpleTransmission</type>
    <joint name="joint_13">
      <hardwareInterface>hardware_interface/EffortJointInterface</hardwareInterface>
    </joint>
    <actuator name="joint_13_motor">
      <mechanicalReduction>1</mechanicalReduction>
      <hardwareInterface>hardware_interface/EffortJointInterface</hardwareInterface>
    </actuator>
  </transmission>
  <transmission name="joint_14_trans">
    <type>transmission_interface/SimpleTransmission</type>
    <joint name="joint_14">
      <hardwareInterface>hardware_interface/EffortJointInterface</hardwareInterface>
    </joint>
    <actuator name="joint_14_motor">
      <mechanicalReduction>1</mechanicalReduction>
      <hardwareInterface>hardware_interface/EffortJointInterface</hardwareInterface>
    </actuator>
  </transmission>
  <transmission name="joint_15_trans">
    <type>transmission_interface/SimpleTransmission</type>
    <joint name="joint_15">
      <hardwareInterface>hardware_interface/EffortJointInterface</hardwareInterface>
    </joint>
    <actuator name="joint_15_motor">
      <mechanicalReduction>1</mechanicalReduction>
      <hardwareInterface>hardware_interface/EffortJointInterface</hardwareInterface>
    </actuator>
  </transmission>
  <gazebo>
    <plugin filename="libgazebo_ros_control.so" name="gazebo_ros_control">
      <robotNamespace>/</robotNamespace>
      <legacyModeNS>true</legacyModeNS>
    </plugin>
  </gazebo>
</robot>

