<?xml version="1.0" ?>


 

<!-- =================================================================================== -->
<!-- |    This document was autogenerated by xacro from src/barrett_hand_description/robots/bh_alone.urdf.xacro | -->
<!-- |    EDITING THIS FILE BY HAND IS NOT RECOMMENDED                                 | -->
<!-- =================================================================================== -->
<robot name="bhand">
  <!-- z-coordinate is not 0 because otherwise the hand base tilts when the simulation is started -->
  
  
  <link name="base_link_6dof">
  </link>
  <joint name="translationX" type="prismatic">
    <parent link="base_link_6dof"/>
    <child link="base_link2"/>
    <origin rpy="0 0 0" xyz="0 0 0"/>
	<axis xyz="1 0 0"/>
    <limit effort="2000.0" lower="-1000" upper="1000.0" velocity="100"/>
  </joint>

  <link name="base_link2">
  </link>

  <joint name="translationY" type="prismatic">
    <parent link="base_link2"/>
    <child link="base_link3"/>
    <origin rpy="0 0 0" xyz="0 0 0"/>
	<axis xyz="0 1 0"/>
    <limit effort="2000.0" lower="-1000" upper="1000.0" velocity="100"/>
  </joint>

 <link name="base_link3">
  </link>

  <joint name="translationZ" type="prismatic">
    <parent link="base_link3"/>
    <child link="base_link4"/>
    <origin rpy="0 0 0" xyz="0 0 0"/>
	<axis xyz="0 0 1"/>
    <limit effort="2000.0" lower="-100" upper="100.0" velocity="100"/>
  </joint>

  <link name="base_link4">
  </link>

  <joint name="rotationX" type="revolute">
    <parent link="base_link4"/>
    <child link="base_link5"/>
    <origin rpy="0 0 0" xyz="0 0 0"/>
	<axis xyz="1 0 0"/>
    <limit effort="20" lower="-100.0" upper="100.0" velocity="0.2"/>

  </joint>

<link name="base_link5">
  </link>

  <joint name="rotationY" type="revolute">
    <parent link="base_link5"/>
    <child link="base_link6"/>
    <origin rpy="0 0 0" xyz="0 0 0"/>
	<axis xyz="0 1 0"/>
    <limit effort="20" lower="-100.0" upper="100.0" velocity="0.2"/>
  </joint>

<link name="base_link6">
  </link>

  <joint name="rotationZ" type="revolute">
    <parent link="base_link6"/>
    <child link="base_link"/>
    <origin rpy="0 0 0" xyz="0 0 0"/>
	<axis xyz="0 0 1"/>
    <limit effort="20" lower="-100.0" upper="100.0" velocity="0.2"/>
  </joint>

  
  
  <link name="base_link">
    <visual>
      <origin rpy="0 0 0" xyz="0 0 0.01"/>
      <geometry>
        <box size="0.001 0.001 0.001"/>
      </geometry>
    </visual>
    <collision>
      <origin rpy="0 0 0" xyz="0 0 0.01"/>
      <geometry>
        <box size="0.001 0.001 0.001"/>
      </geometry>
    </collision>
  </link>
  <joint name="hand_joint" type="fixed">
    <origin rpy="0 0 0" xyz="0 0 0"/>
    <parent link="base_link"/>
    <child link="hand_base_link"/>
  </joint>
  <link name="hand_base_link"/>
  <joint name="bh_base_joint" type="fixed">
    <origin rpy="0 0 0" xyz="0 0 0"/>
    <parent link="hand_base_link"/>
    <child link="bh_base_link"/>
  </joint>
  <!-- HAND BASE_LINK (RED) -->
  <link name="bh_base_link">
    <inertial>
      <mass value="1.0"/>
      <origin xyz="0 0 0"/>
      <inertia ixx="1.0" ixy="0.0" ixz="0.0" iyy="1.00" iyz="0.0" izz="1.00"/>
    </inertial>
    <visual>
      <origin rpy="0 0 0" xyz="0 0 0"/>
      <geometry>
        <mesh filename="barrett_hand/barrett_hand_description/meshes/palm_280.dae"/>
      </geometry>
      <material name="Grey">
        <color rgba="0.75 0.75 0.75 1.0"/>
      </material>
    </visual>
    <collision>
      <origin rpy="0 0 0 " xyz="0 0 0"/>
      <geometry>
        <mesh filename="barrett_hand/barrett_hand_description/meshes/palm_280.dae"/>
      </geometry>
    </collision>
  </link>
  <!-- finger 3 -->
  <!-- finger 32 link -->
  <link name="bh_finger_32_link">
    <inertial>
      <mass value="0.1"/>
      <origin rpy="0 0 0" xyz="0 0 0"/>
      <inertia ixx="0.01" ixy="0" ixz="0" iyy="0.01" iyz="0" izz="0.01"/>
    </inertial>
    <visual>
      <origin rpy="0 0 0" xyz="0 0 0"/>
      <geometry>
        <mesh filename="barrett_hand/barrett_hand_description/meshes/finger.dae"/>
      </geometry>
      <material name="Blue"/>
    </visual>
    <collision>
      <origin rpy="0 0 0" xyz="0 0 0"/>
      <geometry>
        <mesh filename="barrett_hand/barrett_hand_description/meshes/finger.dae"/>
      </geometry>
    </collision>
  </link>
  <!-- joint between BH_finger_31_link and BH_finger_32_link -->
  <joint name="bh_j32_joint" type="revolute">
    <parent link="bh_base_link"/>
    <child link="bh_finger_32_link"/>
    <origin rpy="1.5708 0 1.5708" xyz="0 -0.05 0.0754"/>
    <axis xyz="0 0 -1"/>
    <limit effort="200.0" upper="0.0" lower="2.44" velocity="10.0"/>
  </joint>
  <!-- finger 33 link -->
  <link name="bh_finger_33_link">
    <inertial>
      <mass value="0.1"/>
      <origin rpy="0 0 0" xyz="0 0 0"/>
      <inertia ixx="0.01" ixy="0" ixz="0" iyy="0.01" iyz="0" izz="0.01"/>
    </inertial>
    <visual>
      <origin rpy="0 0 0" xyz="0 0 0"/>
      <geometry>
        <mesh filename="barrett_hand/barrett_hand_description/meshes/finger_tip.dae"/>
      </geometry>
      <material name="Blue"/>
    </visual>
    <collision>
      <origin rpy="0 0 0" xyz="0 0 0"/>
      <geometry>
        <mesh filename="barrett_hand/barrett_hand_description/meshes/finger_tip.dae"/>
      </geometry>
    </collision>
  </link>
  <!-- joint between BH_finger_32_link and BH_finger_33_link -->
  <joint name="bh_j33_joint" type="revolute">
    <parent link="bh_finger_32_link"/>
    <child link="bh_finger_33_link"/>
    <origin rpy="0 0 0" xyz="-0.069936 0.003 0"/>
    <axis xyz="0 0 -1"/>
    <limit effort="100.0" upper="0.00" lower="0.84" velocity="4.0"/>
  </joint>
  <!-- finger 1 -->
  <!-- finger 11 link -->
  <link name="bh_finger_11_link">
    <inertial>
      <mass value="0.1"/>
      <origin rpy="0 0 0" xyz="-0.046 0 0"/>
      <inertia ixx="0.01" ixy="0" ixz="0" iyy="0.01" iyz="0" izz="0.01"/>
    </inertial>
    <visual>
      <origin rpy="0 0 0" xyz="0 0 0"/>
      <geometry>
        <mesh filename="barrett_hand/barrett_hand_description/meshes/knuckle.dae"/>
      </geometry>
      <material name="Green"/>
    </visual>
    <collision>
      <origin rpy="0 0 0" xyz="0 0 0"/>
      <geometry>
        <mesh filename="barrett_hand/barrett_hand_description/meshes/knuckle.dae"/>
      </geometry>
    </collision>
  </link>
  <!-- joint between BH_palm_link and BH_finger_11_link -->
  <joint name="bh_j11_joint" type="revolute">
    <parent link="bh_base_link"/>
    <child link="bh_finger_11_link"/>
    <origin rpy="0 0 -1.5708" xyz="0.025 0 0.0415"/>
    <axis xyz="0 0 -1"/>
    <limit effort="10000.0" upper="0" lower="3.1416" velocity="10.0"/>
  </joint>
  <!-- finger 12 link -->
  <link name="bh_finger_12_link">
    <inertial>
      <mass value="0.1"/>
      <origin rpy="0 0 0" xyz="0 0 0"/>
      <inertia ixx="0.01" ixy="0" ixz="0" iyy="0.01" iyz="0" izz="0.01"/>
    </inertial>
    <visual>
      <origin rpy="0 0 0" xyz="0 0 0"/>
      <geometry>
        <mesh filename="barrett_hand/barrett_hand_description/meshes/finger.dae"/>
      </geometry>
      <material name="Blue"/>
    </visual>
    <collision>
      <origin rpy="0 0 0" xyz="0 0 0"/>
      <geometry>
        <mesh filename="barrett_hand/barrett_hand_description/meshes/finger.dae"/>
      </geometry>
    </collision>
  </link>
  <!-- joint between BH_finger_11_link and BH_finger_12_link -->
  <joint name="bh_j12_joint" type="revolute">
    <parent link="bh_finger_11_link"/>
    <child link="bh_finger_12_link"/>
    <origin rpy="1.5708 0 0" xyz="-0.05 0 0.0339"/>
    <axis xyz="0 0 -1"/>
    <limit effort="200.0" upper="0.0" lower="2.44" velocity="10.0"/>
  </joint>
  <!-- finger 13 link -->
  <link name="bh_finger_13_link">
    <inertial>
      <mass value="0.1"/>
      <origin rpy="0 0 0" xyz="0 0 0"/>
      <inertia ixx="0.01" ixy="0" ixz="0" iyy="0.01" iyz="0" izz="0.01"/>
    </inertial>
    <visual>
      <origin rpy="0 0 0" xyz="0 0 0"/>
      <geometry>
        <mesh filename="barrett_hand/barrett_hand_description/meshes/finger_tip.dae"/>
      </geometry>
      <material name="Blue"/>
    </visual>
    <collision>
      <origin rpy="0 0 0" xyz="0 0 0"/>
      <geometry>
        <mesh filename="barrett_hand/barrett_hand_description/meshes/finger_tip.dae"/>
      </geometry>
    </collision>
  </link>
  <!-- joint between BH_finger_12_link and BH_finger_13_link -->
  <joint name="bh_j13_joint" type="revolute">
    <parent link="bh_finger_12_link"/>
    <child link="bh_finger_13_link"/>
    <origin rpy="0 0 0" xyz="-0.069936 0.003 0"/>
    <axis xyz="0 0 -1"/>
    <limit effort="100.0" upper="0.0" lower="0.84" velocity="4.0"/>
  </joint>
  <!-- finger 2 -->
  <!-- finger 21 link -->
  <link name="bh_finger_21_link">
    <inertial>
      <mass value="0.1"/>
      <origin rpy="0 0 0" xyz="-0.046 0 0"/>
      <inertia ixx="0.01" ixy="0" ixz="0" iyy="0.01" iyz="0" izz="0.01"/>
    </inertial>
    <visual>
      <origin rpy="0 0 0" xyz="0 0 0"/>
      <geometry>
        <mesh filename="barrett_hand/barrett_hand_description/meshes/knuckle.dae"/>
      </geometry>
      <material name="Green"/>
    </visual>
    <collision>
      <origin rpy="0 0 0" xyz="0 0 0"/>
      <geometry>
        <mesh filename="barrett_hand/barrett_hand_description/meshes/knuckle.dae"/>
      </geometry>
    </collision>
  </link>
  <!-- joint between BH_palm_link and BH_finger_21_link -->
  <joint name="bh_j21_joint" type="revolute">
    <parent link="bh_base_link"/>
    <child link="bh_finger_21_link"/>
    <origin rpy="0 0 -1.5708" xyz="-0.025 0 0.0415"/>
    <axis xyz="0 0 1"/>
    <limit effort="10000.0" upper="0" lower="3.1416" velocity="10.0"/>
  </joint>
  <!-- finger 12 link -->
  <link name="bh_finger_22_link">
    <inertial>
      <mass value="0.1"/>
      <origin rpy="0 0 0" xyz="0 0 0"/>
      <inertia ixx="0.01" ixy="0" ixz="0" iyy="0.01" iyz="0" izz="0.01"/>
    </inertial>
    <visual>
      <origin rpy="0 0 0" xyz="0 0 0"/>
      <geometry>
        <mesh filename="barrett_hand/barrett_hand_description/meshes/finger.dae"/>
      </geometry>
      <material name="Blue"/>
    </visual>
    <collision>
      <origin rpy="0 0 0" xyz="0 0 0"/>
      <geometry>
        <mesh filename="barrett_hand/barrett_hand_description/meshes/finger.dae"/>
      </geometry>
    </collision>
  </link>
  <!-- joint between BH_finger_21_link and BH_finger_22_link -->
  <joint name="bh_j22_joint" type="revolute">
    <parent link="bh_finger_21_link"/>
    <child link="bh_finger_22_link"/>
    <origin rpy="1.5708 -8.8281E-17 0" xyz="-0.05 0 0.0339"/>
    <axis xyz="0 0 -1"/>
    <limit effort="200.0" upper="0.0" lower="2.44" velocity="10.0"/>
  </joint>
  <!-- finger 23 link -->
  <link name="bh_finger_23_link">
    <inertial>
      <mass value="0.1"/>
      <origin rpy="0 0 0" xyz="0 0 0"/>
      <inertia ixx="0.01" ixy="0" ixz="0" iyy="0.01" iyz="0" izz="0.01"/>
    </inertial>
    <visual>
      <origin rpy="0 0 0" xyz="0 0 0"/>
      <geometry>
        <mesh filename="barrett_hand/barrett_hand_description/meshes/finger_tip.dae"/>
      </geometry>
      <material name="Blue"/>
    </visual>
    <collision>
      <origin rpy="0 0 0" xyz="0 0 0"/>
      <geometry>
        <mesh filename="barrett_hand/barrett_hand_description/meshes/finger_tip.dae"/>
      </geometry>
    </collision>
  </link>
  <!-- joint between BH_finger_22_link and BH_finger_23_link -->
  <joint name="bh_j23_joint" type="revolute">
    <parent link="bh_finger_22_link"/>
    <child link="bh_finger_23_link"/>
    <origin rpy="0 0 0" xyz="-0.069936 0.003 0"/>
    <axis xyz="0 0 -1"/>
    <limit effort="100.0" upper="0.0" lower="0.84" velocity="4.0"/>
  </joint>

</robot>

