<?xml version="1.0" ?>

<robot name="panda" xmlns:xacro="http://www.ros.org/wiki/xacro">

  <link name="base_link">
  <inertial>
        <origin rpy="0 0 0" xyz="0 0 0" />
        <mass value="1" />
        <inertia ixx="1" ixy="0" ixz="0" iyy="1" iyz="0" izz="1" />
  </inertial>
  </link>


  <joint name="translationX" type="prismatic">
    <parent link="base_link"/>
    <child link="base_link2"/>
    <origin rpy="0 0 0" xyz="0 0 0"/>
	<axis xyz="1 0 0"/>
    <limit effort="20" lower="-1000" upper="1000.0" velocity="1"/>
    <dynamics damping="0.00001"/>
  </joint>

  <link name="base_link2">
  <inertial>
        <origin rpy="0 0 0" xyz="0 0 0" />
        <mass value="1" />
        <inertia ixx="1" ixy="0" ixz="0" iyy="1" iyz="0" izz="1" />
  </inertial>
  </link>

  <joint name="translationY" type="prismatic">
    <parent link="base_link2"/>
    <child link="base_link3"/>
    <origin rpy="0 0 0" xyz="0 0 0"/>
	<axis xyz="0 1 0"/>
    <limit effort="10000" lower="-1000" upper="1000.0" velocity="1"/>
  </joint>

 <link name="base_link3">
 <inertial>
        <origin rpy="0 0 0" xyz="0 0 0" />
        <mass value="1" />
        <inertia ixx="1" ixy="0" ixz="0" iyy="1" iyz="0" izz="1" />
  </inertial>
  </link>

  <joint name="translationZ" type="prismatic">
    <parent link="base_link3"/>
    <child link="base_link4"/>
    <origin rpy="0 0 0" xyz="0 0 0"/>
	<axis xyz="0 0 1"/>
    <limit effort="20" lower="-100" upper="100.0" velocity="0.2"/>
  </joint>

  <link name="base_link4">
  <inertial>
        <origin rpy="0 0 0" xyz="0 0 0" />
        <mass value="1" />
        <inertia ixx="1" ixy="0" ixz="0" iyy="1" iyz="0" izz="1" />
  </inertial>
  </link>

  <joint name="rotationX" type="revolute">
    <parent link="base_link4"/>
    <child link="base_link5"/>
    <origin rpy="0 0 0" xyz="0 0 0"/>
	<axis xyz="1 0 0"/>
    <limit effort="20" lower="-100.0" upper="100.0" velocity="0.2"/>

  </joint>

<link name="base_link5">
<inertial>
        <origin rpy="0 0 0" xyz="0 0 0" />
        <mass value="1" />
        <inertia ixx="1" ixy="0" ixz="0" iyy="1" iyz="0" izz="1" />
  </inertial>
  </link>

  <joint name="rotationY" type="revolute">
    <parent link="base_link5"/>
    <child link="base_link6"/>
    <origin rpy="0 0 0" xyz="0 0 0"/>
	<axis xyz="0 1 0"/>
    <limit effort="20" lower="-100.0" upper="100.0" velocity="0.2"/>
  </joint>

<link name="base_link6">
  <inertial>
        <origin rpy="0 0 0" xyz="0 0 0" />
        <mass value="1" />
        <inertia ixx="1" ixy="0" ixz="0" iyy="1" iyz="0" izz="1" />
  </inertial>
  </link>

  <joint name="rotationZ" type="revolute">
    <parent link="base_link6"/>
    <child link="panda_hand"/>
    <origin rpy="0 0 0" xyz="0 0 0"/>
	<axis xyz="0 0 1"/>
    <limit effort="20" lower="-100.0" upper="100.0" velocity="0.2"/>
  </joint>


  <link name="panda_hand">
    <visual>
      <geometry>
        <mesh filename="package://panda/meshes/visual/hand.stl"/>
      </geometry>
      <material name="panda_gray"/>
    </visual>
    <collision>
      <geometry>
        <mesh filename="package://panda/meshes/collision/hand.stl"/>
      </geometry>
      <material name="panda_gray"/>
    </collision>
    <inertial>
      <origin xyz="0 0 0" rpy="0 0 0"/>
      <mass value="0.68"/>
      <inertia ixx="0.1" ixy="0.0" ixz="0.0" iyy="0.1" iyz="0.0" izz="0.1"/>
    </inertial>
  </link>

  <link name="panda_leftfinger">
    <visual>
      <geometry>
        <mesh filename="package://panda/meshes/visual/finger.stl"/>
      </geometry>
      <material name="panda_gray"/>
    </visual>
    <collision>
      <geometry>
        <mesh filename="package://panda/meshes/collision/finger.stl"/>
      </geometry>
      <material name="panda_gray"/>
    </collision>
    <inertial>
      <origin xyz="0 0 0" rpy="0 0 0"/>
      <mass value="0.01"/>
      <inertia ixx="0.1" ixy="0.0" ixz="0.0" iyy="0.1" iyz="0.0" izz="0.1"/>
    </inertial>
  </link>

  <link name="panda_rightfinger">
    <visual>
      <origin rpy="0 0 3.14159265359" xyz="0 0 0"/>
      <geometry>
        <mesh filename="package://panda/meshes/visual/finger.stl"/>
      </geometry>
      <material name="panda_gray"/>
    </visual>
    <collision>
      <origin rpy="0 0 3.14159265359" xyz="0 0 0"/>
      <geometry>
        <mesh filename="package://panda/meshes/collision/finger.stl"/>
      </geometry>
      <material name="panda_gray"/>
    </collision>
    <inertial>
      <origin xyz="0 0 0" rpy="0 0 0"/>
      <mass value="0.01"/>
      <inertia ixx="0.1" ixy="0.0" ixz="0.0" iyy="0.1" iyz="0.0" izz="0.1"/>
    </inertial>
  </link>
  <joint name="panda_finger_joint1" type="prismatic">
    <parent link="panda_hand"/>
    <child link="panda_leftfinger"/>
    <origin rpy="0 0 0" xyz="0 0 0.0584"/>
    <axis xyz="0 1 0"/>
    <limit effort="100" lower="0.0" upper="0.04" velocity="100.0"/>
    <dynamics damping="0.3"/>
  </joint>
  <joint name="panda_finger_joint2" type="prismatic">
    <parent link="panda_hand"/>
    <child link="panda_rightfinger"/>
    <origin rpy="0 0 0" xyz="0 0 0.0584"/>
    <axis xyz="0 -1 0"/>
    <limit effort="100" lower="0.0" upper="0.04" velocity="100.0"/>
    <mimic joint="panda_finger_joint1"/>
    <dynamics damping="0.3"/>
  </joint>

  <material name="panda_white">
    <color rgba="1. 1. 1. 1."/>
  </material>
  <material name="panda_gray">
    <color rgba=".8 .8 .8 1."/>
  </material>
</robot>
