<?xml version="1.0"?>
<robot name="multipleshapes">
  <link name="base_link">
    <visual>
      <geometry>
        <cylinder length="1" radius="0.000001"/>
      </geometry>
     <material name="transparent"/>
    </visual>
    <inertial>
            <!-- Dummy inertial to avoid warnings -->
			<origin rpy="0 0 0" xyz="0 0 0" />
			<mass value="1" />
			<inertia ixx="1.0" ixy="0.0" ixz="0.0" iyy="1.0" iyz="0.0" izz="1.0" />
	</inertial>
  </link>

  <link name="link1">
    <visual>
      <geometry>
        <sphere radius="0.000001"/>
      </geometry>
    <material name="transparent"/>
    </visual>
    <collision>
      <geometry>
        <sphere radius="0.01"/>
      </geometry>
    </collision>
    <inertial>
            <!-- Dummy inertial to avoid warnings -->
			<origin rpy="0 0 0" xyz="0 0 0" />
			<mass value="1" />
			<inertia ixx="1.0" ixy="0.0" ixz="0.0" iyy="1.0" iyz="0.0" izz="1.0" />
	</inertial>
  </link>


  <joint name="translationY" type="prismatic">
    <parent link="base_link"/>
    <child link="link1"/>
    <origin rpy="0 0 0" xyz="0 0 0.5"/>
	<axis xyz="1 0 0"/>
    <limit effort="10000" lower="-1000" upper="1000.0" velocity="1"/>
  </joint>

   <material name="transparent">
    <color rgba=".8 .8 .8 1"/>
  </material>
</robot>
